Workbook

Sheet Máquinas ACL
A1: ID / Nome da Máquina | B1: Tipo | C1: Localização | D1: Fornecedor / Gestão | E1: Serviços Alojados | F1: Notas
A2: ACL-Físicos | B2: 3 Máquinas Físicas | C2: ACL | D2: ERLOG | E2: Suportam as VMs locais
A3: ACL-VMs | B3: 12 Máquinas Virtuais | C3: ACL | D3: ERLOG | E3: Archeevo, Museu, Biblioteca (Windows), Visita3D
A4: Servidor Dominios | B4: Cloud | C4: dominios.pt | D4: Dominios.pt / ERLOG | E4: Página Principal (WordPress) e Viagem ARF?? | F4: WordPress: ERLOG adiciona ferramentas mas gestão é feita pela ACL. Lento, delay na publicação. Verificar backups e segurança no dominios.pt. Confirmar se a Viagem de Alexandre também está no dominios.pt
A5: Servidor Antigo IST | B5: Físico/VM Antiga | C5: IST (IP: [CENSURADO]) | D5: DSI do IST | E5: Modelos Anatómicos | F5: Recuperar acesso ao site. [Nota interna censurada]. Já recuperado, falta adicionar à ACL.
A6: Infraestrutura ILLLP | B6: - | C6: - | D6: ILLLP | E6: Dicionários, Vocabulário | F6: Possibilidade de migrar ferramentas do ILLLP para a infraestrutura da ACL.
A7: Google | B7: Cloud | C7: Google | D7: Google | E7: Vídeos Institucionais | F7: Possibilidade de criar mirror no Educast e storage local.

Sheet Contactos
A1: Nome | B1: Cargo | C1: E-mail | D1: Aplicações | E1: Responsabilidades / Observações
A2: [CENSURADO] | B2: Consultor Externo | C2: [CENSURADO] | D2: - | E2: Consultor direto do Presidente para o Desafio Digital / Integração Informática.
A3: [CENSURADO] | B3: Mestrando | C3: [CENSURADO] | D3: - | E3: Levantamento e diagnóstico tecnológico.
A4: [CENSURADO] | B4: Coordenador/Dirigente | C4: [CENSURADO] | D4: - | E4: Coordenação geral
A5: [CENSURADO] | B5: Responsável Archeevo e Porbase | C5: [CENSURADO] | D5: Porbase, Archeevo, WordPress, Biblioteca Digital | E5: Coordena Arquivo e Biblioteca Digital. Gestão provisória das licenças Archeevo e Porbase. Edição/publicação no website WordPress
A6: [CENSURADO] | B6: Responsável Tecnológico | C6: [CENSURADO] | D6: WordPress, Museo | E6: Adm. tecnológica (servidor, contas), gestão de licenças e edição/publicação no website WordPress
A7: [CENSURADO] | B7: Técnico Exterior | C7: [CENSURADO] | D7: Informática | E7: Informática
A8: [CENSURADO] | B8: Funcionário | C8: [CENSURADO] | D8: WordPress, YouTube | E8: Edição/publicação no WordPress, levantamento e gestão de vídeos do YouTube.
A9: [CENSURADO] | B9: Bolseiro | C9: [CENSURADO] | D9: WordPress, YouTube | E9: Funcionalidade WordPress e apoio na gestão dos vídeos do youtube.
A10: [CENSURADO] | B10: Funcionária | C10: [CENSURADO] | D10: Museo | E10: Edição/publicação de registos no Museu
A11: [CENSURADO] | B11: Bolseira | C11: [CENSURADO] | D11: Museo | E11: Edição/publicação de registos no Museu
A12: [CENSURADO] | B12: Bolseira | C12: [CENSURADO] | D12: Porbase, Archeevo | E12: Edição/publicação de registos na porbase e Archeevo
... A14: [CENSURADO] | B14: Funcionária | C14: [CENSURADO] | D14: Porbase, Archeevo | E14: Edição/publicação de registos na porbase e Archeevo

Sheet Serviços
A1: Área | B1: Serviço | C1: Software | D1: URL | E1: Servidor | F1: Fornecedor | G1: Custo | H1: Problemas / Notas | I1: IP Máquina
A2: Website Institucional | C2: WordPress | D2: acad-ciencias.pt | E2: dominios.pt | F2: ERLOG (Manutenção, backups), Conteúdos geridos pela ACL | I2: [CENSURADO] | J2: dominios
A3: Biblioteca | B3: Sistema de Gestão de Bibliotecas | C3: mindPrisma | D3: biblioteca.acad-ciencias.pt | F3: Mind | G3: [CENSURADO] | H3: assegurado por plug-in de "livrastrias digital". Triplicação com o porbase e RCAAP. Migração porbase-RCAAP é manual. PDFs estão todos no RCAAP. No PRISMA há PDFs locais de manuscritos digitalizados | I3: [CENSURADO] | J3: ACL
A4: Arquivo Histórico | B4: Sistema de Gestão de Informação de Arquivo Histórico | C4: Archeevo | D4: arquivo.acad-ciencias.pt | F4: Keep Solutions | G4: [CENSURADO] | I4: [CENSURADO]
A5: Museu | B5: Sistema de Gestão de Informação de Museu | C5: MuseoAtlas | D5: museu.acad-ciencias.pt | F5: Keep Solutions | G5: - | I5: [CENSURADO]
A6: ILLLP
A7: Dicionário Histórico-Biográfico | B7: Serviço em linha | C7: WordPress / LeXmart | D7: dhb.acad-ciencias.pt | E7: Gerido pelo ILLLP | F7: ILLLP | G7: [CENSURADO] | I7: [CENSURADO]
A8: Dicionário de Língua Portuguesa | B8: Serviço em linha | C8: LeXmart | D8: dicionario.acad-ciencias.pt | E8: Gerido pelo ILLLP | F8: ILLLP | G8: [CENSURADO] | I8: [CENSURADO]
A9: Vocabulário | B9: Serviço em linha | C9: Joomla! | D9: vocabulario.acad-ciencias.pt | E9: Gerido pelo ILLLP | F9: ILLLP | G9: [CENSURADO] | I9: [CENSURADO]
A10: Acervo Lexicográfico | B10: Serviço em linha | C10: Joomla + YOOtheme Pro | D10: https://acervolexicografico.acad-ciencias.pt/ | E10: a confirmar... | F10: a confirmar... | G10: [CENSURADO] | H10: Confirmar responsabilidade, HTTPS, duplicação HTML e manutenção. | I10: a confirmar...
A11: Objetos Digitais
A12: Museu/Modelos Anatómicos | B12: Conteúdo (obra) em linha - está integrada numa cópia desatualizada do "site" da ACL | D12: Réplica em [CENSURADO] | E12: IST/servidor antigo | F12: DSI do IST | H12: Recuperar acesso ao site. Está num servidor antigo no IST. [Nota interna censurada].
A13: Museu/Galeria ARF | B13: Conteúdo (obra) em linha - está integrada numa cópia desatualizada do "site" da ACL | C13: WordPress | D13: galeria-arf-acad-ciencias.pt | H13: o DNS é estranho... clarificar onde está isto alojado!!! | I13: DNS alojado na FCCN
A14: Museu/Visita 3D | B14: visita 3D à ACL | C14: Matterport | D14: visita3d.acad-ciencias.pt | F14: Desenvolvido por NovaLINCS (tecnologia Matterport) | H14: o URL é da ACL, mas o conteúdo 3D está em tecnologia Matterport (https://matterport.com/), não sendo claro onde está o objeto em si (e consequentemente se pode ser tornado independente disso). Analisar e perceber isto melhor... | I14: [CENSURADO]
A16: Vídeos Institucionais | B16: reiniões e seminários da ACL | C16: YouTube | D16: youtube.com/user/academialx | E16: Google / YouTube | F16: ACL | G16: Gratuito | H16: Criar mirror no Educast (FCCN) e storage local + parceria com FCCN/Arquivo.pt

Sheet Website Institucional
A1: Software (Fornecedor) | B1: WordPress
A2: URL | B2: acad-ciencias.pt
A3: Servidor | B3: dominios.pt (cloud)
A4: Responsável | B4: [CENSURADO], [CENSURADO], ERLOG (Manutenção)
A5: Editores | B5: [CENSURADO], [CENSURADO]
A7: (Recolha 20/01/2026)
A8: Year | B8: POSTS | D8: Type | E8: Quantity | G8: Category | H8: Nº Posts
A9: 2021 | B9: 1 | D9: Image | E9: 1908 | G9: NOTÍCIAS | H9: 245
A10: 2022 | B10: 5 | D10: PDF | E10: 627 | G10: PRÉMIOS | H10: 5
A11: 2023 | B11: 81 | D11: x-font-woff | E11: 5 | G11: OUTROS EVENTOS | H11: 4
A12: 2024 | B12: 79 | D12: DOC/WORD | E12: 4 | G12: CONFERÊNCIAS | H12: 3
A13: 2025 | B13: 83 | D13: zip | E13: 1 | G13: Recrutamento | H13: 3
A14: 2026 | B14: 5 | D14: Video | E14: 1 | G14: Documento | H14: 2
A15: Total | B15: =SUM(B9:B14) -> 254 | D15: csv | E15: 1 | G15: SESSÕES ACADÉMICAS | H15: 0
D16: Total | E16: =SUM(E9:E15) -> 2547 | G16: TODOS OS EVENTOS | H16: 0
D18: Meter tudo por ano

Sheet Biblioteca
A1: Software (Fornecedor) | B1: mindPrisma (Mind)
A2: URL | B2: biblioteca.acad-ciencias.pt
A3: Servidor | B3: Máquina Virtual Local (Windows)
A4: Responsável | B4: [CENSURADO]
A6: Total Registos | B6: (Recolha 08/05/2026) | D6: 70364
A7: Categoria | B7: Filtro | C7: Quantidade | D7: Total
A8: Bibliotecas | B8: Monografias | C8: 38728
A9: Bibliotecas | B9: Livro Antigo | C9: 26213
A10: Bibliotecas | B10: Manuscritos | C10: 4503
A11: Bibliotecas | B11: Iconografia | C11: 813
A12: Bibliotecas | B12: Periódicos | C12: 111
A13: Bibliotecas | B13: Arquivo | C13: 3 | D13: =SUM(C8:C13) -> 70371
A14: Tipo de Documento | B14: Texto | C14: 60754
A15: Tipo de Documento | B15: Manuscrito | C15: 4619
A16: Tipo de Documento | B16: Imagem | C16: 856
A17: Tipo de Documento | B17: Documento electrónico | C17: 129
A18: Tipo de Documento | B18: Cartografia | C18: 61
A19: Tipo de Documento | B19: Música | C19: 29
A20: Tipo de Documento | B20: Multimédia | C20: 11
A21: Tipo de Documento | B21: Partituras | C21: 2
A22: Tipo de Documento | B22: Documento sonoro | C22: 2
A23: Tipo de Documento | B23: Manuscrito (cartografia) | C23: 1
A24: Tipo de Documento | B24: Objecto | C24: 1 | D24: =SUM(C14:C24) -> 66465
A25: Nível Bibliográfico | B25: Monografia | C25: 63544
A26: Nível Bibliográfico | B26: Analítico | C26: 5967
A27: Nível Bibliográfico | B27: Série | C27: 200
A28: Nível Bibliográfico | B28: Miscelânea | C28: 101
A29: Nível Bibliográfico | B29: Recurso integrante | C29: 6 | D29: =SUM(C25:C29) -> 69818
A30: Autor | B30: Convento de Nossa Senhora de Jesus de Lisboa | C30: 15281
A31: Autor | B31: Ordem Terceira de S. Francisco, Convento de Nossa Senhora de Jesus de Lisboa | C31: 13818
A32: Autor | B32: Academia das Ciências de Lisboa | C32: 3248
A33: Autor | B33: Convento de N. S. de Jesus | C33: 1680
A34: Autor | B34: Ordem Terceira de S. Francisco, Convento de N. S. de Jesus | C34: 1645
A35: Autor | B35: Tipografia | C35: 1112
A36: Autor | B36: Convento de N. S. de Jesus de Lisboa | C36: 1078
A37: Autor | B37: Ordem Terceira de S. Francisco. Convento de N. S. de Jesus de Lisboa | C37: 1022
A38: Autor | B38: Ordem Terceira de São Francisco. Convento de Nossa Senhora de Jesus de Lisboa | C38: 937
A39: Autor | B39: Pereira, Francisco Maria Esteves, 1854-1924 | C39: 699
A40: Autor | B40: Montenegro, Artur Pinto de Miranda, 1871-1941 | C40: 661
A41: Autor | B41: Salgado, Vicente, 1732-1802, O.F.M. | C41: 658
...

Sheet Arquivo
A1: Software (Fornecedor) | B1: Archeevo (Keep Solutions)
A2: URL | B2: arquivo.acad-ciencias.pt
A3: Servidor | B3: Máquina Virtual Local (VMware)
A4: Responsáveis | B4: [CENSURADO]
A5: Editores | B5: [CENSURADO], [CENSURADO], [CENSURADO]
A7: Total Registos | B7: (Recolha 08/05/2026) | D7: 5275
A8: Categoria | B8: Filtro | C8: Quantidade | D8: Total cada Categoria
A9: Nível de Descrição | B9: Coleção | C9: 4
A10: Nível de Descrição | B10: Fundo | C10: 1
A11: Nível de Descrição | B11: Secção | C11: 14
A12: Nível de Descrição | B12: Subsecção | C12: 11
A13: Nível de Descrição | B13: Série | C13: 169
A14: Nível de Descrição | B14: Subsérie | C14: 7
A15: Nível de Descrição | B15: Unidade de instalação | C15: 168
A16: Nível de Descrição | B16: Processo | C16: 2199
A17: Nível de Descrição | B17: Documento composto | C17: 451
A18: Nível de Descrição | B18: Documento simples | C18: 2251 | D18: =SUM(C9:C18) -> 5275
A19: Objetos Digitais | B19: Sem objetos digitais | C19: 1980
A20: Objetos Digitais | B20: Com objetos digitais | C20: 3295 | D20: =SUM(C19:C20) -> 5275
A21: Idioma e Escrita | B21: port | C21: 1
A22: Idioma e Escrita | B22: russ | C22: 1
A23: Idioma e Escrita | B23: arab | C23: 2
A24: Idioma e Escrita | B24: alema | C24: 18
A25: Idioma e Escrita | B25: latim | C25: 19
A26: Idioma e Escrita | B26: espanhol | C26: 24
A27: Idioma e Escrita | B27: ingles | C27: 43
A28: Idioma e Escrita | B28: italian | C28: 48
A29: Idioma e Escrita | B29: franc | C29: 146
A30: Idioma e Escrita | B30: portugu | C30: 3481 | D30: =SUM(C21:C30) -> 3783
A32: Nota: Existem dados desde 1710 até 2026

Sheet Museu
A1: Software (Fornecedor) | B1: MuseoAtlas (Keep Solutions)
A2: URL | B2: museu.acad-ciencias.pt
A3: Servidor | B3: Máquina Virtual Local (VMware)
A4: Responsável | B4: [CENSURADO]
A5: Edição | B5: [CENSURADO], [CENSURADO]
A7: Total Registos | B7: (Recolha 08/05/2026) | D7: 275
A8: Categoria | B8: Filtro | C8: Quantidade | D8: Total cada Categoria
A9: Tipo de património | B9: Material móvel | C9: 272
A10: Tipo de património | B10: Onomástico | C10: 3 | D10: =SUM(C9:C10) -> 275
A11: Categorias/Tipologias | B11: Fotografia | C11: 72
A12: Categorias/Tipologias | B12: Retrato | C12: 38
A13: Categorias/Tipologias | B13: Fotografia documental | C13: 29
A14: Categorias/Tipologias | B14: Fotografia arquitectónica | C14: 6
A15: Categorias/Tipologias | B15: Fotógrafo | C15: 2
A16: Categorias/Tipologias | B16: Pintor | C16: 1
A17: Categorias/Tipologias | B17: Pintura | C17: 1 | D17: =SUM(C11:C17) -> 149
A18: Coleções | B18: Tipografia | C18: 199
A19: Coleções | B19: Fotografia | C19: 72
A20: Coleções | B20: Pintura, Desenho e Gravura | C20: 1 | D20: =SUM(C18:C20) -> 272
A21: Autores | B21: Joaquim Manuel da Rocha (1727-1786) | C21: 1
A22: Autores | B22: João Francisco Camacho (1833-1898) | C22: 1
A23: Autores | B23: Júlio Novaes (1867-1925) | C23: 1 | D23: =SUM(C21:C23) -> 3
A24: Localidades | B24: Lisboa | C24: 272 | D24: =SUM(C24) -> 272

Sheet Dashboard Geral
A1: Dashboard Geral — Levantamento ACL
A2: Resumo estatístico dos sistemas, serviços, contactos e registos.
A4: Serviços mapeados | D4: Contactos | G4: Infraestruturas | J4: Registos Museu
A5: ='Dados Dashboard'!B5 -> 11 | D5: ='Dados Dashboard'!B6 -> 13 | G5: ='Dados Dashboard'!B7 -> 6 | J5: ='Dados Dashboard'!B12 -> 275
A8: Posts website | D8: Ficheiros website | G8: Registos Biblioteca | J8: Registos Arquivo
A9: ='Dados Dashboard'!B8 -> 254 | D9: ='Dados Dashboard'!B9 -> 2547 | G9: ='Dados Dashboard'!B10 -> 70364 | J9: ='Dados Dashboard'!B11 -> 5275
A13: Sistema | B13: Quantidade
A14: ='Dados Dashboard'!D5 -> Website posts | B14: ='Dados Dashboard'!E5 -> 254
A15: ='Dados Dashboard'!D6 -> Website ficheiros | B15: ='Dados Dashboard'!E6 -> 2547
A16: ='Dados Dashboard'!D7 -> Biblioteca | B16: ='Dados Dashboard'!E7 -> 70364
A17: ='Dados Dashboard'!D8 -> Arquivo | B17: ='Dados Dashboard'!E8 -> 5275
A18: ='Dados Dashboard'!D9 -> Museu | B18: ='Dados Dashboard'!E9 -> 275

Sheet Dashboard Website
A1: Dashboard Website Institucional
A2: Posts, ficheiros e categorias do WordPress ACL.
A4: Total posts | D4: Total ficheiros | G4: Imagens | J4: Categoria Notícias
A5: ='Website Institucional'!B15 -> 254 | D5: ='Website Institucional'!E16 -> 2547 | G5: ='Website Institucional'!E9 -> 1908 | J5: ='Website Institucional'!H9 -> 245
A9: ='Dados Dashboard'!A15 -> Ano | B9: ='Dados Dashboard'!B15 -> Posts
A10: ='Dados Dashboard'!A16 -> 2021 | B10: ='Dados Dashboard'!B16 -> 1
A11: ='Dados Dashboard'!A17 -> 2022 | B11: ='Dados Dashboard'!B17 -> 5
A12: ='Dados Dashboard'!A18 -> 2023 | B12: ='Dados Dashboard'!B18 -> 81
A13: ='Dados Dashboard'!A19 -> 2024 | B13: ='Dados Dashboard'!B19 -> 79
A14: ='Dados Dashboard'!A20 -> 2025 | B14: ='Dados Dashboard'!B20 -> 83
A15: ='Dados Dashboard'!A21 -> 2026 | B15: ='Dados Dashboard'!B21 -> 5
A27: ='Dados Dashboard'!D15 -> Tipo de ficheiro | B27: ='Dados Dashboard'!E15 -> Quantidade
A28: ='Dados Dashboard'!D16 -> Image | B28: ='Dados Dashboard'!E16 -> 1908
A29: ='Dados Dashboard'!D17 -> PDF | B29: ='Dados Dashboard'!E17 -> 627
A30: ='Dados Dashboard'!D18 -> x-font-woff | B30: ='Dados Dashboard'!E18 -> 5
A31: ='Dados Dashboard'!D19 -> DOC/WORD | B31: ='Dados Dashboard'!E19 -> 4
A32: ='Dados Dashboard'!D20 -> zip | B32: ='Dados Dashboard'!E20 -> 1
A33: ='Dados Dashboard'!D21 -> Video | B33: ='Dados Dashboard'!E21 -> 1
A34: ='Dados Dashboard'!D22 -> csv | B34: ='Dados Dashboard'!E22 -> 1
A45: ='Dados Dashboard'!G15 -> Categoria | B45: ='Dados Dashboard'!H15 -> Posts
A46: ='Dados Dashboard'!G16 -> NOTÍCIAS | B46: ='Dados Dashboard'!H16 -> 245
A47: ='Dados Dashboard'!G17 -> PRÉMIOS | B47: ='Dados Dashboard'!H17 -> 5
A48: ='Dados Dashboard'!G18 -> OUTROS EVENTOS | B48: ='Dados Dashboard'!H18 -> 4
A49: ='Dados Dashboard'!G19 -> CONFERÊNCIAS | B49: ='Dados Dashboard'!H19 -> 3
A50: ='Dados Dashboard'!G20 -> Recrutamento | B50: ='Dados Dashboard'!H20 -> 3
A51: ='Dados Dashboard'!G21 -> Documento | B51: ='Dados Dashboard'!H21 -> 2
A52: ='Dados Dashboard'!G22 -> SESSÕES ACADÉMICAS | B52: ='Dados Dashboard'!H22 -> 0
A53: ='Dados Dashboard'!G23 -> TODOS OS EVENTOS | B53: ='Dados Dashboard'!H23 -> 0

Sheet Dashboard Biblioteca
A1: Dashboard Biblioteca Digital
A2: Distribuição dos registos no mindPrisma por categorias principais.
A4: Total registos | D4: Monografias | G4: Texto | J4: Português
A5: =Biblioteca!D6 -> 70364 | D5: =Biblioteca!C8 -> 38728 | G5: =Biblioteca!C14 -> 60754 | J5: =Biblioteca!C126 -> 45783
A9: ='Dados Dashboard'!A26 -> Filtro | B9: ='Dados Dashboard'!B26 -> Quantidade
A10: ='Dados Dashboard'!A27 -> Monografias | B10: ='Dados Dashboard'!B27 -> 38728
A11: ='Dados Dashboard'!A28 -> Livro Antigo | B11: ='Dados Dashboard'!B28 -> 26213
A12: ='Dados Dashboard'!A29 -> Manuscritos | B12: ='Dados Dashboard'!B29 -> 4503
A13: ='Dados Dashboard'!A30 -> Iconografia | B13: ='Dados Dashboard'!B30 -> 813
A14: ='Dados Dashboard'!A31 -> Periódicos | B14: ='Dados Dashboard'!B31 -> 111
A15: ='Dados Dashboard'!A32 -> Arquivo | B15: ='Dados Dashboard'!B32 -> 3
A27: ='Dados Dashboard'!D26 -> Filtro | B27: ='Dados Dashboard'!E26 -> Quantidade
A28: ='Dados Dashboard'!D27 -> Texto | B28: ='Dados Dashboard'!E27 -> 60754
A29: ='Dados Dashboard'!D28 -> Manuscrito | B29: ='Dados Dashboard'!E28 -> 4619
A30: ='Dados Dashboard'!D29 -> Imagem | B30: ='Dados Dashboard'!E29 -> 856
A31: ='Dados Dashboard'!D30 -> Documento electrónico | B31: ='Dados Dashboard'!E30 -> 129
A32: ='Dados Dashboard'!D31 -> Cartografia | B32: ='Dados Dashboard'!E31 -> 61
A33: ='Dados Dashboard'!D32 -> Música | B33: ='Dados Dashboard'!E32 -> 29
A34: ='Dados Dashboard'!D33 -> Multimédia | B34: ='Dados Dashboard'!E33 -> 11
A35: ='Dados Dashboard'!D34 -> Partituras | B35: ='Dados Dashboard'!E34 -> 2
A36: ='Dados Dashboard'!D35 -> Documento sonoro | B36: ='Dados Dashboard'!E35 -> 2
A37: ='Dados Dashboard'!D36 -> Manuscrito (cartografia) | B37: ='Dados Dashboard'!E36 -> 1
A45: ='Dados Dashboard'!J26 -> Filtro | B45: ='Dados Dashboard'!K26 -> Quantidade
A46: ='Dados Dashboard'!J27 -> Português | B46: ='Dados Dashboard'!K27 -> 45783
A47: ='Dados Dashboard'!J28 -> Latim | B47: ='Dados Dashboard'!K28 -> 11123
A48: ='Dados Dashboard'!J29 -> Francês | B48: ='Dados Dashboard'!K29 -> 5612
A49: ='Dados Dashboard'!J30 -> Espanhol | B49: ='Dados Dashboard'!K30 -> 3922
A50: ='Dados Dashboard'!J31 -> Inglês | B50: ='Dados Dashboard'!K31 -> 2326
A51: ='Dados Dashboard'!J32 -> Italiano | B51: ='Dados Dashboard'!K32 -> 1194
A52: ='Dados Dashboard'!J33 -> Alemão | B52: ='Dados Dashboard'!K33 -> 562
A53: ='Dados Dashboard'!J34 -> Grego antigo (até 1453) | B53: ='Dados Dashboard'!K34 -> 262
A54: ='Dados Dashboard'!J35 -> Árabe | B54: ='Dados Dashboard'!K35 -> 145
A55: ='Dados Dashboard'!J36 -> Hebraico | B55: ='Dados Dashboard'!K36 -> 102

Sheet Dashboard Arquivo
A1: Dashboard Arquivo Histórico
A2: Registos no Archeevo por nível, objetos digitais e idioma.
A4: Total registos | D4: Com objetos digitais | G4: Sem objetos digitais | J4: % com objetos
A5: =Arquivo!D7 -> 5275 | D5: =Arquivo!C20 -> 3295 | G5: =Arquivo!C19 -> 1980 | J5: =Arquivo!C20/Arquivo!D7 -> 0.62464455
A9: ='Dados Dashboard'!A42 -> Filtro | B9: ='Dados Dashboard'!B42 -> Quantidade
A10: ='Dados Dashboard'!A43 -> Coleção | B10: ='Dados Dashboard'!B43 -> 4
A11: ='Dados Dashboard'!A44 -> Fundo | B11: ='Dados Dashboard'!B44 -> 1
A12: ='Dados Dashboard'!A45 -> Secção | B12: ='Dados Dashboard'!B45 -> 14
A13: ='Dados Dashboard'!A46 -> Subsecção | B13: ='Dados Dashboard'!B46 -> 11
A14: ='Dados Dashboard'!A47 -> Série | B14: ='Dados Dashboard'!B47 -> 169
A15: ='Dados Dashboard'!A48 -> Subsérie | B15: ='Dados Dashboard'!B48 -> 7
A16: ='Dados Dashboard'!A49 -> Unidade de instalação | B16: ='Dados Dashboard'!B49 -> 168
A17: ='Dados Dashboard'!A50 -> Processo | B17: ='Dados Dashboard'!B50 -> 2199
A18: ='Dados Dashboard'!A51 -> Documento composto | B18: ='Dados Dashboard'!B51 -> 451
A19: ='Dados Dashboard'!A52 -> Documento simples | B19: ='Dados Dashboard'!B52 -> 2251
A27: ='Dados Dashboard'!D42 -> Filtro | B27: ='Dados Dashboard'!E42 -> Quantidade
A28: ='Dados Dashboard'!D43 -> Sem objetos digitais | B28: ='Dados Dashboard'!E43 -> 1980
A29: ='Dados Dashboard'!D44 -> Com objetos digitais | B29: ='Dados Dashboard'!E44 -> 3295
A45: ='Dados Dashboard'!G42 -> Filtro | B45: ='Dados Dashboard'!H42 -> Quantidade
A46: ='Dados Dashboard'!G43 -> port | B46: ='Dados Dashboard'!H43 -> 1
A47: ='Dados Dashboard'!G44 -> russ | B47: ='Dados Dashboard'!H44 -> 1
A48: ='Dados Dashboard'!G45 -> arab | B48: ='Dados Dashboard'!H45 -> 2
A49: ='Dados Dashboard'!G46 -> alema | B49: ='Dados Dashboard'!H46 -> 18
A50: ='Dados Dashboard'!G47 -> latim | B50: ='Dados Dashboard'!H47 -> 19
A51: ='Dados Dashboard'!G48 -> espanhol | B51: ='Dados Dashboard'!H48 -> 24
A52: ='Dados Dashboard'!G49 -> ingles | B52: ='Dados Dashboard'!H49 -> 43
A53: ='Dados Dashboard'!G50 -> italian | B53: ='Dados Dashboard'!H50 -> 48
A54: ='Dados Dashboard'!G51 -> franc | B54: ='Dados Dashboard'!H51 -> 146
A55: ='Dados Dashboard'!G52 -> portugu | B55: ='Dados Dashboard'!H52 -> 3481

Sheet Dashboard Museu
A1: Dashboard Museu
A2: Registos do MuseoAtlas por património, tipologia, coleção e localidade.
A4: Total registos | D4: Material móvel | G4: Tipografia | J4: Lisboa
A5: =Museu!D7 -> 275 | D5: =Museu!C9 -> 272 | G5: =Museu!C18 -> 199 | J5: =Museu!C24 -> 272
A9: ='Dados Dashboard'!A58 -> Filtro | B9: ='Dados Dashboard'!B58 -> Quantidade
A10: ='Dados Dashboard'!A59 -> Material móvel | B10: ='Dados Dashboard'!B59 -> 272
A11: ='Dados Dashboard'!A60 -> Onomástico | B11: ='Dados Dashboard'!B60 -> 3
A27: ='Dados Dashboard'!D58 -> Filtro | B27: ='Dados Dashboard'!E58 -> Quantidade
A28: ='Dados Dashboard'!D59 -> Fotografia | B28: ='Dados Dashboard'!E59 -> 72
A29: ='Dados Dashboard'!D60 -> Retrato | B29: ='Dados Dashboard'!E60 -> 38
A30: ='Dados Dashboard'!D61 -> Fotografia documental | B30: ='Dados Dashboard'!E61 -> 29
A31: ='Dados Dashboard'!D62 -> Fotografia arquitectónica | B31: ='Dados Dashboard'!E62 -> 6
A32: ='Dados Dashboard'!D63 -> Fotógrafo | B32: ='Dados Dashboard'!E63 -> 2
A33: ='Dados Dashboard'!D64 -> Pintor | B33: ='Dados Dashboard'!E64 -> 1
A34: ='Dados Dashboard'!D65 -> Pintura | B34: ='Dados Dashboard'!E65 -> 1
A45: ='Dados Dashboard'!G58 -> Filtro | B45: ='Dados Dashboard'!H58 -> Quantidade
A46: ='Dados Dashboard'!G59 -> Tipografia | B46: ='Dados Dashboard'!H59 -> 199
A47: ='Dados Dashboard'!G60 -> Fotografia | B47: ='Dados Dashboard'!H60 -> 72
A48: ='Dados Dashboard'!G61 -> Pintura, Desenho e Gravura | B48: ='Dados Dashboard'!H61 -> 1

Sheet Dados Dashboard
A1: Dados de apoio aos dashboards
A2: Tabelas derivadas/ligadas às folhas originais.
A4: Indicador | B4: Valor | D4: Sistema | E4: Registos
A5: Serviços mapeados | B5: =COUNTA(Serviços!B2:B16) -> 11 | D5: Website posts | E5: ='Website Institucional'!B15 -> 254
A6: Contactos | B6: =COUNTA(Contactos!A2:A14) -> 13 | D6: Website ficheiros | E6: ='Website Institucional'!E16 -> 2547
A7: Infraestruturas/Máquinas | B7: =COUNTA('Máquinas ACL'!A2:A7) -> 6 | D7: Biblioteca | E7: =Biblioteca!D6 -> 70364
A8: Posts website | B8: ='Website Institucional'!B15 -> 254 | D8: Arquivo | E8: =Arquivo!D7 -> 5275
A9: Ficheiros website | B9: ='Website Institucional'!E16 -> 2547 | D9: Museu | E9: =Museu!D7 -> 275
A10: Registos Biblioteca | B10: =Biblioteca!D6 -> 70364
A11: Registos Arquivo | B11: =Arquivo!D7 -> 5275
A12: Registos Museu | B12: =Museu!D7 -> 275
A15: Ano | B15: Posts | D15: Tipo de ficheiro | E15: Quantidade | G15: Categoria | H15: Posts
A16: ='Website Institucional'!A9 -> 2021 | B16: ='Website Institucional'!B9 -> 1 | D16: ='Website Institucional'!D9 -> Image | E16: ='Website Institucional'!E9 -> 1908 | G16: ='Website Institucional'!G9 -> NOTÍCIAS | H16: ='Website Institucional'!H9 -> 245
A17: ='Website Institucional'!A10 -> 2022 | B17: ='Website Institucional'!B10 -> 5 | D17: ='Website Institucional'!D10 -> PDF | E17: ='Website Institucional'!E10 -> 627 | G17: ='Website Institucional'!G10 -> PRÉMIOS | H17: ='Website Institucional'!H10 -> 5
A18: ='Website Institucional'!A11 -> 2023 | B18: ='Website Institucional'!B11 -> 81 | D18: ='Website Institucional'!D11 -> x-font-woff | E18: ='Website Institucional'!E11 -> 5 | G18: ='Website Institucional'!G11 -> OUTROS EVENTOS | H18: ='Website Institucional'!H11 -> 4
A19: ='Website Institucional'!A12 -> 2024 | B19: ='Website Institucional'!B12 -> 79 | D19: ='Website Institucional'!D12 -> DOC/WORD | E19: ='Website Institucional'!E12 -> 4 | G19: ='Website Institucional'!G12 -> CONFERÊNCIAS | H19: ='Website Institucional'!H12 -> 3
A20: ='Website Institucional'!A13 -> 2025 | B20: ='Website Institucional'!B13 -> 83 | D20: ='Website Institucional'!D13 -> zip | E20: ='Website Institucional'!E13 -> 1 | G20: ='Website Institucional'!G13 -> Recrutamento | H20: ='Website Institucional'!H13 -> 3
A21: ='Website Institucional'!A14 -> 2026 | B21: ='Website Institucional'!B14 -> 5 | D21: ='Website Institucional'!D14 -> Video | E21: ='Website Institucional'!E14 -> 1 | G21: ='Website Institucional'!G14 -> Documento | H21: ='Website Institucional'!H14 -> 2
D22: ='Website Institucional'!D15 -> csv | E22: ='Website Institucional'!E15 -> 1 | G22: ='Website Institucional'!G15 -> SESSÕES ACADÉMICAS | H22: ='Website Institucional'!H15 -> 0
G23: ='Website Institucional'!G16 -> TODOS OS EVENTOS | H23: ='Website Institucional'!H16 -> 0
A26: Filtro | B26: Quantidade | D26: Filtro | E26: Quantidade | G26: Filtro | H26: Quantidade | J26: Filtro | K26: Quantidade | M26: Filtro | N26: Quantidade
A27: =Biblioteca!B8 -> Monografias | B27: =Biblioteca!C8 -> 38728 | D27: =Biblioteca!B14 -> Texto | E27: =Biblioteca!C14 -> 60754 | G27: =Biblioteca!B25 -> Monografia | H27: =Biblioteca!C25 -> 63544 | J27: =Biblioteca!B126 -> Português | K27: =Biblioteca!C126 -> 45783 | M27: =Biblioteca!B174 -> Adulto | N27: =Biblioteca!C174 -> 39191
A28: =Biblioteca!B9 -> Livro Antigo | B28: =Biblioteca!C9 -> 26213 | D28: =Biblioteca!B15 -> Manuscrito | E28: =Biblioteca!C15 -> 4619 | G28: =Biblioteca!B26 -> Analítico | H28: =Biblioteca!C26 -> 5967 | J28: =Biblioteca!B127 -> Latim | K28: =Biblioteca!C127 -> 11123 | M28: =Biblioteca!B175 -> Especializado | N28: =Biblioteca!C175 -> 29752
A29: =Biblioteca!B10 -> Manuscritos | B29: =Biblioteca!C10 -> 4503 | D29: =Biblioteca!B16 -> Imagem | E29: =Biblioteca!C16 -> 856 | G29: =Biblioteca!B27 -> Série | H29: =Biblioteca!C27 -> 200 | J29: =Biblioteca!B128 -> Francês | K29: =Biblioteca!C128 -> 5612 | M29: =Biblioteca!B176 -> Jovem | N29: =Biblioteca!C176 -> 276
A30: =Biblioteca!B11 -> Iconografia | B30: =Biblioteca!C11 -> 813 | D30: =Biblioteca!B17 -> Documento electrónico | E30: =Biblioteca!C17 -> 129 | G30: =Biblioteca!B28 -> Miscelânea | H30: =Biblioteca!C28 -> 101 | J30: =Biblioteca!B129 -> Espanhol | K30: =Biblioteca!C129 -> 3922 | M30: =Biblioteca!B177 -> Dos 9-14 anos | N30: =Biblioteca!C177 -> 60
A31: =Biblioteca!B12 -> Periódicos | B31: =Biblioteca!C12 -> 111 | D31: =Biblioteca!B18 -> Cartografia | E31: =Biblioteca!C18 -> 61 | G31: =Biblioteca!B29 -> Recurso integrante | H31: =Biblioteca!C29 -> 6 | J31: =Biblioteca!B130 -> Inglês | K31: =Biblioteca!C130 -> 2326 | M31: =Biblioteca!B178 -> Juvenil | N31: =Biblioteca!C178 -> 59
A32: =Biblioteca!B13 -> Arquivo | B32: =Biblioteca!C13 -> 3 | D32: =Biblioteca!B19 -> Música | E32: =Biblioteca!C19 -> 29 | J32: =Biblioteca!B131 -> Italiano | K32: =Biblioteca!C131 -> 1194 | M32: =Biblioteca!B179 -> Desconhecido | N32: =Biblioteca!C179 -> 20
D33: =Biblioteca!B20 -> Multimédia | E33: =Biblioteca!C20 -> 11 | J33: =Biblioteca!B132 -> Alemão | K33: =Biblioteca!C132 -> 562
D34: =Biblioteca!B21 -> Partituras | E34: =Biblioteca!C21 -> 2 | J34: =Biblioteca!B133 -> Grego antigo (até 1453) | K34: =Biblioteca!C133 -> 262
D35: =Biblioteca!B22 -> Documento sonoro | E35: =Biblioteca!C22 -> 2 | J35: =Biblioteca!B134 -> Árabe | K35: =Biblioteca!C134 -> 145
D36: =Biblioteca!B23 -> Manuscrito (cartografia) | E36: =Biblioteca!C23 -> 1 | J36: =Biblioteca!B135 -> Hebraico | K36: =Biblioteca!C135 -> 102
A42: Filtro | B42: Quantidade | D42: Filtro | E42: Quantidade | G42: Filtro | H42: Quantidade
A43: =Arquivo!B9 -> Coleção | B43: =Arquivo!C9 -> 4 | D43: =Arquivo!B19 -> Sem objetos digitais | E43: =Arquivo!C19 -> 1980 | G43: =Arquivo!B21 -> port | H43: =Arquivo!C21 -> 1
A44: =Arquivo!B10 -> Fundo | B44: =Arquivo!C10 -> 1 | D44: =Arquivo!B20 -> Com objetos digitais | E44: =Arquivo!C20 -> 3295 | G44: =Arquivo!B22 -> russ | H44: =Arquivo!C22 -> 1
A45: =Arquivo!B11 -> Secção | B45: =Arquivo!C11 -> 14 | G45: =Arquivo!B23 -> arab | H45: =Arquivo!C23 -> 2
A46: =Arquivo!B12 -> Subsecção | B46: =Arquivo!C12 -> 11 | G46: =Arquivo!B24 -> alema | H46: =Arquivo!C24 -> 18
A47: =Arquivo!B13 -> Série | B47: =Arquivo!C13 -> 169 | G47: =Arquivo!B25 -> latim | H47: =Arquivo!C25 -> 19
A48: =Arquivo!B14 -> Subsérie | B48: =Arquivo!C14 -> 7 | G48: =Arquivo!B26 -> espanhol | H48: =Arquivo!C26 -> 24
A49: =Arquivo!B15 -> Unidade de instalação | B49: =Arquivo!C15 -> 168 | G49: =Arquivo!B27 -> ingles | H49: =Arquivo!C27 -> 43
A50: =Arquivo!B16 -> Processo | B50: =Arquivo!C16 -> 2199 | G50: =Arquivo!B28 -> italian | H50: =Arquivo!C28 -> 48
...
